<?xml version="1.0" encoding="utf-8"?>
<!-- This URDF was automatically created by SolidWorks to URDF Exporter! Originally created by Stephen Brawner (brawner@gmail.com) 
     Commit Version: 1.5.1-0-g916b5db  Build Version: 1.5.7152.31018
     For more information, please see http://wiki.ros.org/sw_urdf_exporter -->
<robot
  name="atomgrip">
  <link
    name="base_link">
    <inertial>
      <origin
        xyz="-2.4727E-05 1.7347E-18 0.0099736"
        rpy="0 0 0" />
      <mass
        value="4.4396" />
      <inertia
        ixx="0.011264"
        ixy="0"
        ixz="-3.9899E-07"
        iyy="0.011256"
        iyz="-1.5217E-19"
        izz="0.022225" />
    </inertial>
    <visual>
      <origin
        xyz="0 0 0"
        rpy="0 0 0" />
      <geometry>
        <mesh
          filename="package://atomgrip/meshes/base_link.STL" />
      </geometry>
      <material
        name="">
        <color
          rgba="1 0.72157 0.32941 1" />
      </material>
    </visual>
    <collision>
      <origin
        xyz="0 0 0"
        rpy="0 0 0" />
      <geometry>
        <mesh
          filename="package://atomgrip/meshes/base_link.STL" />
      </geometry>
    </collision>
  </link>
  <link
    name="base2_link">
    <inertial>
      <origin
        xyz="-8.6736E-19 -1.4674E-05 0.013592"
        rpy="0 0 0" />
      <mass
        value="3.0365" />
      <inertia
        ixx="0.0054148"
        ixy="1.0842E-19"
        ixz="-1.5177E-19"
        iyy="0.0062539"
        iyz="1.7114E-06"
        izz="0.010383" />
    </inertial>
    <visual>
      <origin
        xyz="0 0 20"
        rpy="0 0 0" />
      <geometry>
        <mesh
          filename="package://atomgrip/meshes/base2_link.STL" />
      </geometry>
      <material
        name="">
        <color
          rgba="1 0.72157 0.32941 1" />
      </material>
    </visual>
    <collision>
      <origin
        xyz="0 0 0"
        rpy="0 0 0" />
      <geometry>
        <mesh
          filename="package://atomgrip/meshes/base2_link.STL" />
      </geometry>
    </collision>
  </link>
  <joint
    name="base2_joint"
    type="revolute">
    <origin
      xyz="0 0 0.02"
      rpy="0 0 2.33" />
    <parent
      link="base_link" />
    <child
      link="base2_link" />
    <axis
      xyz="0 0 1" />
    <limit
      lower="-3.141"
      upper="3.141"
      effort="10"
      velocity="1" />
  </joint>
  <link
    name="shoulder2elbow1_link">
    <inertial>
      <origin
        xyz="-0.038907 -0.01 0.0075"
        rpy="0 0 0" />
      <mass
        value="0.53191" />
      <inertia
        ixx="6.1002E-05"
        ixy="1.1011E-19"
        ixz="-1.5185E-06"
        iyy="0.0011553"
        iyz="-4.4046E-20"
        izz="0.0011967" />
    </inertial>
    <visual>
      <origin
        xyz="0 0 0" 
        rpy="0 0 0" />
      <geometry>
        <mesh
          filename="package://atomgrip/meshes/test1.stl" />
      </geometry>0
      <material
        name="">
        <color
          rgba="1 0.72157 0.32941 1" />
      </material>
    </visual>
    <collision>
      <origin
        xyz="0 0 0"
        rpy="0 0 0" />
      <geometry>
        <mesh
          filename="package://atomgrip/meshes/test1.stl" />
      </geometry>
    </collision>
  </link>
  <joint
    name="shoulder2elbow1_joint"
    type="revolute">
    <origin
      xyz="59 10 73"
      rpy="1.5708 3.142 1.5708" />
    <parent
      link="base2_link" />
    <child
      link="shoulder2elbow1_link" />
    <axis
      xyz="0 0 1" />
    <limit
      lower="-1.571"
      upper="1.571"
      effort="10"
      velocity="1" />
  </joint>
  <link
    name="elbow2twist1_link">
    <inertial>
      <origin
        xyz="-0.059349 3.2472E-11 -0.013252"
        rpy="0 0 0" />
      <mass
        value="0.63576" />
      <inertia
        ixx="7.6234E-05"
        ixy="8.5501E-13"
        ixz="6.0719E-13"
        iyy="0.002212"
        iyz="-1.6854E-14"
        izz="0.0022649" />
    </inertial>
    <visual>
      <origin
        xyz="0 0 0"
        rpy="0 0 0" />
      <geometry>
        <mesh
          filename="package://atomgrip/meshes/elbow2twist1_link.STL" />
      </geometry>
      <material
        name="">
        <color
          rgba="1 0.72157 0.32941 1" />
      </material>
    </visual>
    <collision>
      <origin
        xyz="0 0 0"
        rpy="0 0 0" />
      <geometry>
        <mesh
          filename="package://atomgrip/meshes/elbow2twist1_link.STL" />
      </geometry>
    </collision>
  </link>
  <joint
    name="elboe2twist1_joint"
    type="revolute">
    <origin
      xyz="-119 0 -16"
      rpy="-3.14159265358979 0 2.15203310865128" />
    <parent
      link="shoulder2elbow1_link" />
    <child
      link="elbow2twist1_link" />
    <axis
      xyz="0 0 1" />
    <limit
      lower="0"
      upper="3.141"
      effort="10"
      velocity="1" />
  </joint>
  <link
    name="twist_link">
    <inertial>
      <origin
        xyz="1.07448372976826E-08 0.0390661320531351 0.0371379342080336"
        rpy="0 0 0" />
      <mass
        value="0.54181" />
      <inertia
        ixx="0.001388"
        ixy="2.0288E-10"
        ixz="-5.7174E-10"
        iyy="0.00077126"
        iyz="7.8041E-06"
        izz="0.0006648" />
    </inertial>
    <visual>
      <origin
        xyz="0 0 0"
        rpy="0 0 0" />
      <geometry>
        <mesh
          filename="package://atomgrip/meshes/twist_link.STL" />
      </geometry>
      <material
        name="acrylic">
        <color
          rgba="1 0.72157 0.32941 1" />
      </material>
    </visual>
    <collision>
      <origin
        xyz="0 0 0"
        rpy="0 0 0" />
      <geometry>
        <mesh
          filename="package://atomgrip/meshes/twist_link.STL" />
      </geometry>
    </collision>
  </link>
  <joint
    name="twist_joint"
    type="continuous">
    <origin
      xyz="-120 0 -5"
      rpy="0 0 1.5707963267949" />
    <parent
      link="elbow2twist1_link" />
    <child
      link="twist_link" />
    <axis
      xyz="0 0 -1" />
    <limit
      lower="0"
      upper="0"
      effort="10"
      velocity="1" />
  </joint>
  <link
    name="Gripper1_link">
    <inertial>
      <origin
        xyz="-5.55111512312578E-17 -2.77555756156289E-17 0.00144453500235753"
        rpy="0 0 0" />
      <mass
        value="0.000308029324600948" />
      <inertia
        ixx="1.57864125961541E-08"
        ixy="-1.21233658527303E-23"
        ixz="1.86115637824431E-24"
        iyy="1.72478352184127E-09"
        iyz="-3.05022850878929E-24"
        izz="1.64023226180906E-08" />
    </inertial>
    <visual>
      <origin
        xyz="0 0 0"
        rpy="0 0 0" />
      <geometry>
        <mesh
          filename="package://atomgrip/meshes/Gripper1_link.STL" />
      </geometry>
      <material
        name="">
        <color
          rgba="0 0 0 1" />
      </material>
    </visual>
    <collision>
      <origin
        xyz="0 0 0"
        rpy="0 0 0" />
      <geometry>
        <mesh
          filename="package://atomgrip/meshes/Gripper1_link.STL" />
      </geometry>
    </collision>
  </link>
  <joint
    name="Gripper1_joint"
    type="revolute">
    <origin
      xyz="-2 95 38"
      rpy="1.5707963267949 1.5701 0" />
    <parent
      link="twist_link" />
    <child
      link="Gripper1_link" />
    <axis
      xyz="0 0 -1" />
    <limit
      lower="-1.57"
      upper="1.57"
      effort="0"
      velocity="0" />
  </joint>
  <link
    name="Gripper2.1_link">
    <inertial>
      <origin
        xyz="0 0.000902500024634628 0.00273409113717277"
        rpy="0 0 0" />
      <mass
        value="0.000802695785022661" />
      <inertia
        ixx="2.04526485535668E-08"
        ixy="2.02659250075492E-23"
        ixz="1.28212994945719E-23"
        iyy="4.01345338566827E-08"
        iyz="5.69892763771812E-09"
        izz="3.22135146497723E-08" />
    </inertial>
    <visual>
      <origin
        xyz="0 0 0"
        rpy="0 0 0" />
      <geometry>
        <mesh
          filename="package://atomgrip/meshes/Gripper2.1_link.STL" />
      </geometry>
      <material
        name="">
        <color
          rgba="0.647058823529412 0.619607843137255 0.588235294117647 1" />
      </material>
    </visual>
    <collision>
      <origin
        xyz="0 0 0"
        rpy="0 0 0" />
      <geometry>
        <mesh
          filename="package://atomgrip/meshes/Gripper2.1_link.STL" />
      </geometry>
    </collision>
  </link>
  <joint
    name="Gripper2.1_joint"
    type="continuous">
    <origin
      xyz="0 5 -3"
      rpy="3.14159265358979 0 3.14159265358979" />
    <parent
      link="Gripper1_link" />
    <child
      link="Gripper2.1_link" />
    <axis
      xyz="0 0 -1" />
  </joint>
  <link
    name="Gripper2.2_link">
    <inertial>
      <origin
        xyz="0 0.000902500024634573 0.00273409113717277"
        rpy="0 0 0" />
      <mass
        value="0.000802695785022658" />
      <inertia
        ixx="2.04526485535668E-08"
        ixy="-1.24077091882954E-24"
        ixz="-2.48154183765908E-24"
        iyy="4.01345338566826E-08"
        iyz="5.69892763771813E-09"
        izz="3.22135146497721E-08" />
    </inertial>
    <visual>
      <origin
        xyz="0 0 0"
        rpy="0 0 0" />
      <geometry>
        <mesh
          filename="package://atomgrip/meshes/Gripper2.2_link.STL" />
      </geometry>
      <material
        name="">
        <color
          rgba="0.647058823529412 0.619607843137255 0.588235294117647 1" />
      </material>
    </visual>
    <collision>
      <origin
        xyz="0 0 0"
        rpy="0 0 0" />
      <geometry>
        <mesh
          filename="package://atomgrip/meshes/Gripper2.2_link.STL" />
      </geometry>
    </collision>
  </link>
  <joint
    name="Gripper2.2_joint"
    type="continuous">
    <origin
      xyz="0 -5 -3"
      rpy="-3.14159265358979 0 0" />
    <parent
      link="Gripper1_link" />
    <child
      link="Gripper2.2_link" />
    <axis
      xyz="0 0 -1" />
  </joint>
  <link
    name="Gripper3_link">
    <inertial>
      <origin
        xyz="-0.000489828020000443 0.00150000006718251 -0.0313545629406169"
        rpy="0 0 0" />
      <mass
        value="0.00418804587945458" />
      <inertia
        ixx="1.37292715797285E-06"
        ixy="6.94512978693469E-15"
        ixz="4.01013698687832E-08"
        iyy="2.00026573911708E-06"
        iyz="-4.06227747668214E-15"
        izz="6.33608934057656E-07" />
    </inertial>
    <visual>
      <origin
        xyz="0 0 0"
        rpy="0 0 0" />
      <geometry>
        <mesh
          filename="package://atomgrip/meshes/Gripper3_link.STL" />
      </geometry>
      <material
        name="">
        <color
          rgba="0.647058823529412 0.619607843137255 0.588235294117647 1" />
      </material>
    </visual>
    <collision>
      <origin
        xyz="0 0 0"
        rpy="0 0 0" />
      <geometry>
        <mesh
          filename="package://atomgrip/meshes/Gripper3_link.STL" />
      </geometry>
    </collision>
  </link>
  <joint
    name="Gripper3_joint"
    type="continuous">
    <origin
      xyz="0 -6.5 1"
      rpy="3.14159265358979 0 -3.14159265358979" />
    <parent
      link="Gripper2.2_link" />
    <child
      link="Gripper3_link" />
    <axis
      xyz="0 0 -1" />
  </joint>
  <link
    name="Gripper4.1_link">
    <inertial>
      <origin
        xyz="-0.0056632123953004 0.00134615051202581 0.00149999999999995"
        rpy="0 0 0" />
      <mass
        value="0.0019627521866613" />
      <inertia
        ixx="6.81631270097617E-08"
        ixy="2.09591233316627E-08"
        ixz="-4.96308367531817E-24"
        iyy="2.78036989310812E-07"
        iyz="-5.54211010410529E-23"
        izz="3.43255988040581E-07" />
    </inertial>
    <visual>
      <origin
        xyz="0 0 0"
        rpy="0 0 0" />
      <geometry>
        <mesh
          filename="package://atomgrip/meshes/Gripper4.1_link.STL" />
      </geometry>
      <material
        name="">
        <color
          rgba="0.647058823529412 0.619607843137255 0.588235294117647 1" />
      </material>
    </visual>
    <collision>
      <origin
        xyz="0 0 0"
        rpy="0 0 0" />
      <geometry>
        <mesh
          filename="package://atomgrip/meshes/Gripper4.1_link.STL" />
      </geometry>
    </collision>
  </link>
  <joint
    name="Gripper4.1_joint"
    type="revolute">
    <origin
      xyz="-12 3 -28"
      rpy="-1.57079632679489 -1.36586679681116 0" />
    <parent
      link="Gripper3_link" />
    <child
      link="Gripper4.1_link" />
    <axis
      xyz="0 0 -1" />
    <limit
      lower="-1.517"
      upper="1.517"
      effort="0"
      velocity="0" />
  </joint>
  <link
    name="Gripper5.1_link">
    <inertial>
      <origin
        xyz="-0.0307762066469282 -0.0146044173900614 -0.00149999999999997"
        rpy="0 0 0" />
      <mass
        value="0.00146871763406109" />
      <inertia
        ixx="6.96756987728522E-08"
        ixy="1.46795920686148E-07"
        ixz="8.27180612553028E-23"
        iyy="4.0257341490677E-07"
        iyz="-6.86559908419013E-23"
        izz="4.7004603722853E-07" />
    </inertial>
    <visual>
      <origin
        xyz="0 0 0"
        rpy="0 0 0" />
      <geometry>
        <mesh
          filename="package://atomgrip/meshes/Gripper5.1_link.STL" />
      </geometry>
      <material
        name="">
        <color
          rgba="0.647058823529412 0.619607843137255 0.588235294117647 1" />
      </material>
    </visual>
    <collision>
      <origin
        xyz="0 0 0"
        rpy="0 0 0" />
      <geometry>
        <mesh
          filename="package://atomgrip/meshes/Gripper5.1_link.STL" />
      </geometry>
    </collision>
  </link>
  <joint
    name="Gripper5.1_joint"
    type="continuous">
    <origin
      xyz="-31 4 3"
      rpy="3.142 0 -0.671" />
    <parent
      link="Gripper4.1_link" />
    <child
      link="Gripper5.1_link" />
    <axis
      xyz="0 0 1" />
  </joint>
  <link
    name="Gripper4.2_link">
    <inertial>
      <origin
        xyz="-0.00566321239530032 0.00134615051202577 0.00149999999999997"
        rpy="0 0 0" />
      <mass
        value="0.0019627521866613" />
      <inertia
        ixx="6.81631270097615E-08"
        ixy="2.09591233316625E-08"
        ixz="-3.97046694025453E-23"
        iyy="2.78036989310811E-07"
        iyz="3.63959469523332E-23"
        izz="3.4325598804058E-07" />
    </inertial>
    <visual>
      <origin
        xyz="0 0 0"
        rpy="0 0 0" />
      <geometry>
        <mesh
          filename="package://atomgrip/meshes/Gripper4.2_link.STL" />
      </geometry>
      <material
        name="">
        <color
          rgba="0.647058823529412 0.619607843137255 0.588235294117647 1" />
      </material>
    </visual>
    <collision>
      <origin
        xyz="0 0 0"
        rpy="0 0 0" />
      <geometry>
        <mesh
          filename="package://atomgrip/meshes/Gripper4.2_link.STL" />
      </geometry>
    </collision>
  </link>
  <joint
    name="Gripper4.2_joint"
    type="revolute">
    <origin
      xyz="15 6 -28"
      rpy="-1.57079632679494 -1.271 -3.14159265358975" />
    <parent
      link="Gripper3_link" />
    <child
      link="Gripper4.2_link" />
    <axis
      xyz="0 0 -1" />
    <limit
      lower="-1.571"
      upper="1.571"
      effort="0"
      velocity="0" />
  </joint>
  <link
    name="Gripper5.2_link">
    <inertial>
      <origin
        xyz="-0.0237454614720194 0.00393636292072587 -0.00149999999999997"
        rpy="0 0 0" />
      <mass
        value="0.00146871763406109" />
      <inertia
        ixx="4.03152207786004E-08"
        ixy="1.04465154923335E-07"
        ixz="4.79764755280756E-23"
        iyy="4.31933892901021E-07"
        iyz="-9.92616735063633E-24"
        izz="4.7004603722853E-07" />
    </inertial>
    <visual>
      <origin
        xyz="0 0 0"
        rpy="0 0 0" />
      <geometry>
        <mesh
          filename="package://atomgrip/meshes/Gripper5.2_link.STL" />
      </geometry>
      <material
        name="">
        <color
          rgba="0.647058823529412 0.619607843137255 0.588235294117647 1" />
      </material>
    </visual>
    <collision>
      <origin
        xyz="0 0 0"
        rpy="0 0 0" />
      <geometry>
        <mesh
          filename="package://atomgrip/meshes/Gripper5.2_link.STL" />
      </geometry>
    </collision>
  </link>
  <joint
    name="Gripper5.2_joint"
    type="continuous">
    <origin
      xyz="-31 4 -3"
      rpy="3.14159265358979 0 -0.7" />
    <parent
      link="Gripper4.2_link" />
    <child
      link="Gripper5.2_link" />
    <axis
      xyz="0 0 1" />
  </joint>
  <link
    name="shoulder2elbow2.2_link">
    <inertial>
      <origin
        xyz="-0.038907 -0.01 0.097452"
        rpy="0 0 0" />
     <mass
        value="0.53191" />
      <inertia
        ixx="6.1001E-05"
        ixy="6.1156E-19"
        ixz="5.5057E-21"
        iyy="0.0011553"
        iyz="-1.3553E-20"
        izz="0.0011967" />
    </inertial>
    <visual>
      <origin
        xyz="0 0 0"
        rpy="0 0 0" />
      <geometry>
        <mesh
          filename="package://atomgrip/meshes/test1.stl" />
      </geometry>
      <material
        name="acrylic">
        <color
          rgba="1 0.72157 0.32941 1" />
      </material>
    </visual>
    <collision>
      <origin
        xyz="0 0 0"
        rpy="0 0 0" />
      <geometry>
        <mesh
          filename="package://atomgrip/meshes/test1.stl" />
      </geometry>
    </collision>
  </link>
  <joint
    name="shoulder2elbow2.2_joint"
    type="revolute">
    <origin
      xyz="-31 12 72"
      rpy="1.5707963267949 -3.142 1.5707963267949" />
    <parent
      link="base2_link" />
    <child
      link="shoulder2elbow2.2_link" />
    <axis
      xyz="0 0 -1" />
    <limit
      lower="-1.571"
      upper="1.571"
      effort="10"
      velocity="1" />
  </joint>
  <link
    name="elbow2twist2.2_link">
    <inertial>
      <origin
        xyz="0.0010394 0 0.0075"
        rpy="0 0 0" />
      <mass
        value="0.66764" />
      <inertia
        ixx="7.7799E-05"
        ixy="2.3209E-19"
        ixz="1.243E-19"
        iyy="0.0023482"
        iyz="-5.421E-20"
        izz="0.0024014" />
    </inertial>
    <visual>
      <origin
        xyz="0 0 0"
        rpy="0 0 0" />
      <geometry>
        <mesh
          filename="package://atomgrip/meshes/elbow2twist2.2_link.STL" />
      </geometry>
      <material
        name="acrylic">
        <color
          rgba="1 0.72157 0.32941 1" />
      </material>
    </visual>
    <collision>
      <origin
        xyz="0 0 0"
        rpy="0 0 0" />
      <geometry>
        <mesh
          filename="package://atomgrip/meshes/elbow2twist2.2_link.STL" />
      </geometry>
    </collision>
  </link>
  <joint
    name="elbow2twist2.2_joint"
    type="revolute">
    <origin
      xyz="-117 0 13"
      rpy="3.14159265358979 0 2.15203310865129" />
    <parent
      link="shoulder2elbow2.2_link" />
    <child
      link="elbow2twist2.2_link" />
    <axis
      xyz="0 0 1" />
    <limit
      lower="0"
      upper="3.142"
      effort="10"
      velocity="1" />
  </joint>
</robot>