<?xml version="1.0" encoding="utf-8"?>
<!-- This URDF was automatically created by SolidWorks to URDF Exporter! Originally created by Stephen Brawner (brawner@gmail.com) 
     Commit Version: 1.5.1-0-g916b5db  Build Version: 1.5.7152.31018
     For more information, please see http://wiki.ros.org/sw_urdf_exporter -->
<robot
  name="atom_urdf">
  <link
    name="base_link">
    <inertial>
      <origin
        xyz="-2.4727E-05 1.7347E-18 0.0099736"
        rpy="0 0 0" />
      <mass
        value="5" />
      <inertia
        ixx="0.011264"
        ixy="0"
        ixz="-3.9899E-07"
        iyy="0.011256"
        iyz="-1.54E-19"
        izz="0.022225" />
    </inertial>
    <visual>
      <origin
        xyz="0 0 0"
        rpy="0 0 0" />
      <geometry>
        <mesh
          filename="package://atom_urdf/meshes/base_link.STL" />
      </geometry>
      <material
        name="acrylic">
        <color
          rgba="1 0.72157 0.32941 1" />
      </material>
    </visual>
    <collision>
      <origin
        xyz="0 0 0"
        rpy="0 0 0" />
      <geometry>
        <mesh
          filename="package://atom_urdf/meshes/base_link.STL" />
      </geometry>
    </collision>
  </link>
  <link
    name="base2_link">
    <inertial>
      <origin
        xyz="0 -1.4674E-05 0.023592"
        rpy="0 0 0" />
      <mass
        value="2" />
      <inertia
        ixx="0.0054148"
        ixy="8.1315E-20"
        ixz="-2.0078E-19"
        iyy="0.0062539"
        iyz="1.7114E-06"
        izz="0.010383" />
    </inertial>
    <visual>
      <origin
        xyz="0 0 20"
        rpy="0 0 0" />
      <geometry>
        <mesh
          filename="package://atom_urdf/meshes/base2_link.STL" />
      </geometry>
      <material
        name="acrylic">
        <color
          rgba="1 0.72157 0.32941 1" />
      </material>
    </visual>
    <collision>
      <origin
        xyz="0 0 0"
        rpy="0 0 0" />
      <geometry>
        <mesh
          filename="package://atom_urdf/meshes/base2_link.STL" />
      </geometry>
    </collision>
  </link>
  <joint
    name="base2_joint"
    type="revolute">
    <origin
      xyz="0 0 0.01"
      rpy="0 0 2.33" />
    <parent
      link="base_link" />
    <child
      link="base2_link" />
    <axis
      xyz="0 0 1" />
    <limit
      lower="-3.141"
      upper="3.141"
      effort="10"
      velocity="1" />
  </joint>
  <link
    name="shoulder2elbow1_link">
    <inertial>
      <origin
        xyz="-0.06 -5.5511E-17 0.0011"
        rpy="0 0 0" />
      <mass
        value="0.53191" />
      <inertia
        ixx="6.1002E-05"
        ixy="-7.7927E-20"
        ixz="-1.5185E-06"
        iyy="0.0011553"
        iyz="4.4046E-20"
        izz="0.0011967" />
    </inertial>
    <visual>
      <origin
        xyz="48 53 58"
        rpy="0 0 0" />
      <geometry>
        <mesh
          filename="package://atom_urdf/meshes/shoulder2elbow1_link.STL" />
      </geometry>
      <material
        name="acrylic">
        <color
          rgba="1 0.72157 0.32941 1" />
      </material>
    </visual>
    <collision>
      <origin
        xyz="0 0 0"
        rpy="0 0 0" />
      <geometry>
        <mesh
          filename="package://atom_urdf/meshes/shoulder2elbow1_link.STL" />
      </geometry>
    </collision>
  </link>
  <joint
    name="shoulder2elbow1_joint"
    type="revolute">
    <origin
      xyz="-0.0314 0.0088 0.062"
      rpy="1.5708 0.62809 -1.5708" />
    <parent
      link="base2_link" />
    <child
      link="shoulder2elbow1_link" />
    <axis
      xyz="0 0 1" />
    <limit
      lower="-3.141"
      upper="3.141"
      effort="10"
      velocity="1" />
  </joint>
  <link
    name="elbow2twist1_link">
    <inertial>
      <origin
        xyz="0.059349 3.2473E-11 0.0075"
        rpy="0 0 0" />
      <mass
        value="0.6" />
      <inertia
        ixx="7.6234E-05"
        ixy="-8.5501E-13"
        ixz="6.0719E-13"
        iyy="0.002212"
        iyz="1.6854E-14"
        izz="0.0022649" />
    </inertial>
    <visual>
      <origin
        xyz="0 0 0"
        rpy="0 0 0" />
      <geometry>
        <mesh
          filename="package://atom_urdf/meshes/elbow2twist1_link.STL" />
      </geometry>
      <material
        name="acrylic">
        <color
          rgba="1 0.72157 0.32941 1" />
      </material>
    </visual>
    <collision>
      <origin
        xyz="0 0 0"
        rpy="0 0 0" />
      <geometry>
        <mesh
          filename="package://atom_urdf/meshes/elbow2twist1_link.STL" />
      </geometry>
    </collision>
  </link>
  <joint
    name="elboe2twist1_joint"
    type="revolute">
    <origin
      xyz="-0.12 0 -0.0064"
      rpy="-3.1416 0 -2.152" />
    <parent
      link="shoulder2elbow1_link" />
    <child
      link="elbow2twist1_link" />
    <axis
      xyz="0 0 1" />
    <limit
      lower="-3.141"
      upper="3.141"
      effort="10"
      velocity="1" />
  </joint>
  <link
    name="twist_link">
    <inertial>
      <origin
        xyz="9.3271E-09 0.039066 0.037138"
        rpy="0 0 0" />
      <mass
        value="0.2" />
      <inertia
        ixx="0.001388"
        ixy="2.0288E-10"
        ixz="-5.7174E-10"
        iyy="0.00077126"
        iyz="7.8041E-06"
        izz="0.0006648" />
    </inertial>
    <visual>
      <origin
        xyz="0 0 0"
        rpy="0 0 0" />
      <geometry>
        <mesh
          filename="package://atom_urdf/meshes/twist_link.STL" />
      </geometry>
      <material
        name="acrylic">
        <color
          rgba="1 0.72157 0.32941 1" />
      </material>
    </visual>
    <collision>
      <origin
        xyz="0 0 0"
        rpy="0 0 0" />
      <geometry>
        <mesh
          filename="package://atom_urdf/meshes/twist_link.STL" />
      </geometry>
    </collision>
  </link>
  <joint
    name="twist_joint"
    type="continuous">
    <origin
      xyz="0.12 0 0.075"
      rpy="3.1416 0 1.5708" />
    <parent
      link="elbow2twist1_link" />
    <child
      link="twist_link" />
    <axis
      xyz="0 0 -1" />
    <limit
      lower="0"
      upper="0"
      effort="10"
      velocity="1" />
  </joint>
  <link
    name="shoulder2elbow2.2_link">
    <inertial>
      <origin
        xyz="0.06 5.5511E-17 -0.0011476"
        rpy="0 0 0" />
      <mass
        value="0.53191" />
      <inertia
        ixx="6.1001E-05"
        ixy="1.6941E-21"
        ixz="-5.294E-20"
        iyy="0.0011553"
        iyz="-6.7763E-21"
        izz="0.0011967" />
    </inertial>
    <visual>
      <origin
        xyz="0 0 0"
        rpy="0 0 0" />
      <geometry>
        <mesh
          filename="package://atom_urdf/meshes/shoulder2elbow2.2_link.STL" />
      </geometry>
      <material
        name="acrylic">
        <color
          rgba="1 0.72157 0.32941 1" />
      </material>
    </visual>
    <collision>
      <origin
        xyz="0 0 0"
        rpy="0 0 0" />
      <geometry>
        <mesh
          filename="package://atom_urdf/meshes/shoulder2elbow2.2_link.STL" />
      </geometry>
    </collision>
  </link>
  <joint
    name="shoulder2elbow2.2_joint"
    type="revolute">
    <origin
      xyz="0.0586 0.0088 0.062"
      rpy="1.5708 -0.62809 1.5708" />
    <parent
      link="base2_link" />
    <child
      link="shoulder2elbow2.2_link" />
    <axis
      xyz="0 0 -1" />
    <limit
      lower="-3.141"
      upper="3.141"
      effort="10"
      velocity="1" />
  </joint>
  <link
    name="elbow2twist2.2_link">
    <inertial>
      <origin
        xyz="0.058961 0 0.0075"
        rpy="0 0 0" />
      <mass
        value="0.6" />
      <inertia
        ixx="7.7799E-05"
        ixy="-3.4728E-19"
        ixz="1.351E-19"
        iyy="0.0023482"
        iyz="5.421E-20"
        izz="0.0024014" />
    </inertial>
    <visual>
      <origin
        xyz="0 0 0"
        rpy="0 0 0" />
      <geometry>
        <mesh
          filename="package://atom_urdf/meshes/elbow2twist2.2_link.STL" />
      </geometry>
      <material
        name="acrylic">
        <color
          rgba="1 0.72157 0.32941 1" />
      </material>
    </visual>
    <collision>
      <origin
        xyz="0 0 0"
        rpy="0 0 0" />
      <geometry>
        <mesh
          filename="package://atom_urdf/meshes/elbow2twist2.2_link.STL" />
      </geometry>
    </collision>
  </link>
  <joint
    name="elbow2twist2.2_joint"
    type="revolute">
    <origin
      xyz="0.12 0 -0.0236"
      rpy="0 0 -0.98956" />
    <parent
      link="shoulder2elbow2.2_link" />
    <child
      link="elbow2twist2.2_link" />
    <axis
      xyz="0 0 -1" />
    <limit
      lower="-3.141"
      upper="3.141"
      effort="10"
      velocity="1" />
  </joint>
</robot>