<?xml version="1.0" encoding="utf-8"?>
<!-- This URDF was automatically created by SolidWorks to URDF Exporter! Originally created by Stephen Brawner (brawner@gmail.com) 
     Commit Version: 1.5.1-0-g916b5db  Build Version: 1.5.7152.31018
     For more information, please see http://wiki.ros.org/sw_urdf_exporter -->
<robot
  name="atomgrip1">
  <link
    name="base_link">
    <inertial>
      <origin
        xyz="-2.47274120865545E-05 1.73472347597681E-18 0.00997358604267652"
        rpy="0 0 0" />
      <mass
        value="4.43956506959753" />
      <inertia
        ixx="0.011264086471396"
        ixy="0"
        ixz="-3.98990158034621E-07"
        iyy="0.0112561237846214"
        iyz="-1.53891138663516E-19"
        izz="0.0222246652404969" />
    </inertial>
    <visual>
      <origin
        xyz="0 0 0"
        rpy="0 0 0" />
      <geometry>
        <mesh
          filename="package://atomgrip1/meshes/base_link.STL" />
      </geometry>
      <material
        name="acrylic">
        <color
          rgba="1 0.72156862745098 0.329411764705882 1" />
      </material>
    </visual>
    <collision>
      <origin
        xyz="0 0 0"
        rpy="0 0 0" />
      <geometry>
        <mesh
          filename="package://atomgrip1/meshes/base_link.STL" />
      </geometry>
    </collision>
  </link>
  <link
    name="base2_link">
    <inertial>
      <origin
        xyz="-8.6736E-19 -1.4674E-05 0.013592"
        rpy="0 0 0" />
      <mass
        value="3.03649454915767" />
      <inertia
        ixx="0.00625389630329675"
        ixy="-1.71138067876824E-06"
        ixz="-1.76182853028894E-19"
        iyy="0.0103833691748017"
        iyz="6.62427629793006E-20"
        izz="0.00541479393702098" />
    </inertial>
    <visual>
      <origin
        xyz="0 0 20"
        rpy="0 0 0" />
      <geometry>
        <mesh
          filename="package://atomgrip1/meshes/base2_link.STL" />
      </geometry>
      <material
        name="acrylic">
        <color
          rgba="1 0.72156862745098 0.329411764705882 1" />
      </material>
    </visual>
    <collision>
      <origin
        xyz="0 0 0"
        rpy="0 0 0" />
      <geometry>
        <mesh
          filename="package://atomgrip1/meshes/base2_link.STL" />
      </geometry>
    </collision>
  </link>
  <joint
    name="base2_joint"
    type="revolute">
    <origin
      xyz="0 0 0.02"
      rpy="0 0 2.33" />
    <parent
      link="base_link" />
    <child
      link="base2_link" />
    <axis
      xyz="0 0 1" />
    <limit
      lower="-3.141"
      upper="3.141"
      effort="10"
      velocity="1" />
  </joint>
  <link
    name="shoulder2elbow1_link">
    <inertial>
      <origin
        xyz="0 0 0"
        rpy="0 0 0" />
      <mass
        value="0.531909704004155" />
      <inertia
        ixx="6.1002475052105E-05"
        ixy="1.8126505071242E-19"
        ixz="-1.51847375562047E-06"
        iyy="0.00115530783124693"
        iyz="-2.03287907341032E-20"
        izz="0.0011967441684999" />
    </inertial>
    <visual>
      <origin
        xyz="0 0 0"
        rpy="0 0 0" />
      <geometry>
        <mesh
          filename="package://atomgrip1/meshes/shoulder2elbow1_link.STL" />
      </geometry>
      <material
        name="acrylic">
        <color
          rgba="1 0.72156862745098 0.329411764705882 1" />
      </material>
    </visual>
    <collision>
      <origin
        xyz="0 0 0"
        rpy="0 0 0" />
      <geometry>
        <mesh
          filename="package://atomgrip1/meshes/shoulder2elbow1_link.STL" />
      </geometry>
    </collision>
  </link>
  <joint
    name="shoulder2elbow1_joint"
    type="revolute">
    <origin
      xyz="59 10 73"
      rpy="1.5708 3.142 1.5708" />
    <parent
      link="base2_link" />
    <child
      link="shoulder2elbow1_link" />
    <axis
      xyz="0 0 1" />
    <limit
      lower="-1.571"
      upper="1.571"
      effort="10"
      velocity="1" />
  </joint>
  <link
    name="elbow2twist1_link">
    <inertial>
      <origin
        xyz="-0.059349 3.2472E-11 -0.013252"
        rpy="0 0 0" />
      <mass
        value="0.635762030380392" />
      <inertia
        ixx="7.62342936147976E-05"
        ixy="-8.88655275532507E-13"
        ixz="6.39689243403303E-13"
        iyy="0.00221201698107452"
        iyz="1.39181082701697E-14"
        izz="0.00226493473056416" />
    </inertial>
    <visual>
      <origin
        xyz="0 0 0"
        rpy="0 0 0" />
      <geometry>
        <mesh
          filename="package://atomgrip1/meshes/elbow2twist1_link.STL" />
      </geometry>
      <material
        name="acrylic">
        <color
          rgba="1 0.72156862745098 0.329411764705882 1" />
      </material>
    </visual>
    <collision>
      <origin
        xyz="0 0 0"
        rpy="0 0 0" />
      <geometry>
        <mesh
          filename="package://atomgrip1/meshes/elbow2twist1_link.STL" />
      </geometry>
    </collision>
  </link>
  <joint
    name="elboe2twist1_joint"
    type="revolute">
    <origin
      xyz="119 0 -16"
      rpy="-3.14159265358979 0 3.141" />
    <parent
      link="shoulder2elbow1_link" />
    <child
      link="elbow2twist1_link" />
    <axis
      xyz="0 0 1" />
    <limit
      lower="0"
      upper="3.141"
      effort="10"
      velocity="1" />
  </joint>
  <link
    name="twist_link">
    <inertial>
      <origin
        xyz="1.07448372421715E-08 0.0390661320531351 0.0371379342080336"
        rpy="0 0 0" />
      <mass
        value="0.5418135868326" />
      <inertia
        ixx="0.00138801724351832"
        ixy="2.60055734759013E-10"
        ixz="2.1259747949124E-10"
        iyy="0.000771257774086178"
        iyz="7.80376054974566E-06"
        izz="0.000664799889820858" />
    </inertial>
    <visual>
      <origin
        xyz="0 0 0"
        rpy="0 0 0" />
      <geometry>
        <mesh
          filename="package://atomgrip1/meshes/twist_link.STL" />
      </geometry>
      <material
        name="acrylic">
        <color
          rgba="1 0.72156862745098 0.329411764705882 1" />
      </material>
    </visual>
    <collision>
      <origin
        xyz="0 0 0"
        rpy="0 0 0" />
      <geometry>
        <mesh
          filename="package://atomgrip1/meshes/twist_link.STL" />
      </geometry>
    </collision>
  </link>
  <joint
    name="twist_joint"
    type="fixed">
    <origin
      xyz="-120 0 -5"
      rpy="0 0 1.5707963267949" />
    <parent
      link="elbow2twist1_link" />
    <child
      link="twist_link" />
    <axis
      xyz="-0.517368585384651 -0.855458844697503 -0.0228015763906594" />
    <limit
      lower="0"
      upper="0"
      effort="10"
      velocity="1" />
  </joint>
  <link
    name="Gripper1_link">
    <inertial>
      <origin
        xyz="-5.55111512312578E-17 -2.77555756156289E-17 0.00144453500235753"
        rpy="0 0 0" />
      <mass
        value="0.000308029324600948" />
      <inertia
        ixx="1.57864125961541E-08"
        ixy="-1.33641367715599E-23"
        ixz="2.8951321439356E-24"
        iyy="1.72478352184127E-09"
        iyz="-2.27474668452083E-24"
        izz="1.64023226180906E-08" />
    </inertial>
    <visual>
      <origin
        xyz="0 0 0"
        rpy="0 0 0" />
      <geometry>
        <mesh
          filename="package://atomgrip1/meshes/Gripper1_link.STL" />
      </geometry>
      <material
        name="">
        <color
          rgba="0 0 0 1" />
      </material>
    </visual>
    <collision>
      <origin
        xyz="0 0 0"
        rpy="0 0 0" />
      <geometry>
        <mesh
          filename="package://atomgrip1/meshes/Gripper1_link.STL" />
      </geometry>
    </collision>
  </link>
  <joint
    name="Gripper1_joint"
    type="revolute">
    <origin
      xyz="-2 95 38"
      rpy="1.5707963267949 1.5701 0" />
    <parent
      link="twist_link" />
    <child
      link="Gripper1_link" />
    <axis
      xyz="0 0 -1" />
    <limit
      lower="-1.57"
      upper="1.57"
      effort="0"
      velocity="0" />
  </joint>
  <link
    name="Gripper2.1_link">
    <inertial>
      <origin
        xyz="0 0.0009025000246346 0.00273409113717271"
        rpy="0 0 0" />
      <mass
        value="0.00080269578502266" />
      <inertia
        ixx="2.04526485535668E-08"
        ixy="2.35746474577613E-23"
        ixz="1.24077091882954E-23"
        iyy="4.01345338566827E-08"
        iyz="5.69892763771812E-09"
        izz="3.22135146497723E-08" />
    </inertial>
    <visual>
      <origin
        xyz="0 0 0"
        rpy="0 0 0" />
      <geometry>
        <mesh
          filename="package://atomgrip1/meshes/Gripper2.1_link.STL" />
      </geometry>
      <material
        name="">
        <color
          rgba="0.647058823529412 0.619607843137255 0.588235294117647 1" />
      </material>
    </visual>
    <collision>
      <origin
        xyz="0 0 0"
        rpy="0 0 0" />
      <geometry>
        <mesh
          filename="package://atomgrip1/meshes/Gripper2.1_link.STL" />
      </geometry>
    </collision>
  </link>
  <joint
    name="Gripper2.1_joint"
    type="fixed">
    <origin
      xyz="0 5 -3"
      rpy="3.14159265358979 0 3.14159265358979" />
    <parent
      link="Gripper1_link" />
    <child
      link="Gripper2.1_link" />
    <axis
      xyz="0 0 -1" />
  </joint>
  <link
    name="Gripper2.2_link">
    <inertial>
      <origin
        xyz="0 0.000902500024634573 0.00273409113717277"
        rpy="0 0 0" />
      <mass
        value="0.000802695785022658" />
      <inertia
        ixx="2.04526485535668E-08"
        ixy="-2.27474668452083E-24"
        ixz="-8.27180612553028E-25"
        iyy="4.01345338566826E-08"
        iyz="5.69892763771813E-09"
        izz="3.22135146497721E-08" />
    </inertial>
    <visual>
      <origin
        xyz="0 0 0"
        rpy="0 0 0" />
      <geometry>
        <mesh
          filename="package://atomgrip1/meshes/Gripper2.2_link.STL" />
      </geometry>
      <material
        name="">
        <color
          rgba="0.647058823529412 0.619607843137255 0.588235294117647 1" />
      </material>
    </visual>
    <collision>
      <origin
        xyz="0 0 0"
        rpy="0 0 0" />
      <geometry>
        <mesh
          filename="package://atomgrip1/meshes/Gripper2.2_link.STL" />
      </geometry>
    </collision>
  </link>
  <joint
    name="Gripper2.2_joint"
    type="fixed">
    <origin
      xyz="0 -5 -3"
      rpy="-3.14159265358979 0 0" />
    <parent
      link="Gripper1_link" />
    <child
      link="Gripper2.2_link" />
    <axis
      xyz="0 0 -1" />
  </joint>
  <link
    name="Gripper3_link">
    <inertial>
      <origin
        xyz="-0.000489828020000471 0.00150000006718248 -0.0313545629406169"
        rpy="0 0 0" />
      <mass
        value="0.00418804587945457" />
      <inertia
        ixx="1.37292715797285E-06"
        ixy="6.94512953547179E-15"
        ixz="4.0101369868783E-08"
        iyy="2.00026573911708E-06"
        iyz="-4.06227768844037E-15"
        izz="6.33608934057656E-07" />
    </inertial>
    <visual>
      <origin
        xyz="0 0 0"
        rpy="0 0 0" />
      <geometry>
        <mesh
          filename="package://atomgrip1/meshes/Gripper3_link.STL" />
      </geometry>
      <material
        name="">
        <color
          rgba="0.647058823529412 0.619607843137255 0.588235294117647 1" />
      </material>
    </visual>
    <collision>
      <origin
        xyz="0 0 0"
        rpy="0 0 0" />
      <geometry>
        <mesh
          filename="package://atomgrip1/meshes/Gripper3_link.STL" />
      </geometry>
    </collision>
  </link>
  <joint
    name="Gripper3_joint"
    type="fixed">
    <origin
      xyz="0 -6.5 1"
      rpy="3.14159265358979 0 -3.14159265358979" />
    <parent
      link="Gripper2.2_link" />
    <child
      link="Gripper3_link" />
    <axis
      xyz="0 0 -1" />
  </joint>
  <link
    name="Gripper4.1_link">
    <inertial>
      <origin
        xyz="-0.00566321239530035 0.00134615051202583 0.00149999999999997"
        rpy="0 0 0" />
      <mass
        value="0.0019627521866613" />
      <inertia
        ixx="6.81631270097616E-08"
        ixy="2.09591233316627E-08"
        ixz="-4.96308367531817E-24"
        iyy="2.78036989310812E-07"
        iyz="-1.57164316385075E-23"
        izz="3.43255988040581E-07" />
    </inertial>
    <visual>
      <origin
        xyz="0 0 0"
        rpy="0 0 0" />
      <geometry>
        <mesh
          filename="package://atomgrip1/meshes/Gripper4.1_link.STL" />
      </geometry>
      <material
        name="">
        <color
          rgba="0.647058823529412 0.619607843137255 0.588235294117647 1" />
      </material>
    </visual>
    <collision>
      <origin
        xyz="0 0 0"
        rpy="0 0 0" />
      <geometry>
        <mesh
          filename="package://atomgrip1/meshes/Gripper4.1_link.STL" />
      </geometry>
    </collision>
  </link>
  <joint
    name="Gripper4.1_joint"
    type="revolute">
    <origin
      xyz="-12 3 -28"
      rpy="-1.57079632679489 -1.36586679681116 0" />
    <parent
      link="Gripper3_link" />
    <child
      link="Gripper4.1_link" />
    <axis
      xyz="0 0 -1" />
    <limit
      lower="-1.517"
      upper="1.517"
      effort="0"
      velocity="0" />
  </joint>
  <link
    name="Gripper5.1_link">
    <inertial>
      <origin
        xyz="-0.0307762066469282 -0.0146044173900614 -0.00149999999999997"
        rpy="0 0 0" />
      <mass
        value="0.00146871763406109" />
      <inertia
        ixx="6.96756987728521E-08"
        ixy="1.46795920686148E-07"
        ixz="1.20768369432742E-22"
        iyy="4.0257341490677E-07"
        iyz="9.92616735063633E-24"
        izz="4.7004603722853E-07" />
    </inertial>
    <visual>
      <origin
        xyz="0 0 0"
        rpy="0 0 0" />
      <geometry>
        <mesh
          filename="package://atomgrip1/meshes/Gripper5.1_link.STL" />
      </geometry>
      <material
        name="">
        <color
          rgba="0.647058823529412 0.619607843137255 0.588235294117647 1" />
      </material>
    </visual>
    <collision>
      <origin
        xyz="0 0 0"
        rpy="0 0 0" />
      <geometry>
        <mesh
          filename="package://atomgrip1/meshes/Gripper5.1_link.STL" />
      </geometry>
    </collision>
  </link>
  <joint
    name="Gripper5.1_joint"
    type="fixed">
    <origin
      xyz="-31 4 3"
      rpy="3.142 0 -0.671" />
    <parent
      link="Gripper4.1_link" />
    <child
      link="Gripper5.1_link" />
    <axis
      xyz="0 0 1" />
  </joint>
  <link
    name="Gripper4.2_link">
    <inertial>
      <origin
        xyz="-0.00566321239530032 0.00134615051202577 0.00149999999999997"
        rpy="0 0 0" />
      <mass
        value="0.0019627521866613" />
      <inertia
        ixx="6.81631270097615E-08"
        ixy="2.09591233316625E-08"
        ixz="-1.65436122510606E-24"
        iyy="2.78036989310811E-07"
        iyz="2.64697796016969E-23"
        izz="3.4325598804058E-07" />
    </inertial>
    <visual>
      <origin
        xyz="0 0 0"
        rpy="0 0 0" />
      <geometry>
        <mesh
          filename="package://atomgrip1/meshes/Gripper4.2_link.STL" />
      </geometry>
      <material
        name="">
        <color
          rgba="0.647058823529412 0.619607843137255 0.588235294117647 1" />
      </material>
    </visual>
    <collision>
      <origin
        xyz="0 0 0"
        rpy="0 0 0" />
      <geometry>
        <mesh
          filename="package://atomgrip1/meshes/Gripper4.2_link.STL" />
      </geometry>
    </collision>
  </link>
  <joint
    name="Gripper4.2_joint"
    type="revolute">
    <origin
      xyz="15 6 -28"
      rpy="-1.57079632679494 -1.271 -3.14159265358975" />
    <parent
      link="Gripper3_link" />
    <child
      link="Gripper4.2_link" />
    <axis
      xyz="0 0 -1" />
    <limit
      lower="-1.571"
      upper="1.571"
      effort="0"
      velocity="0" />
  </joint>
  <link
    name="Gripper5.2_link">
    <inertial>
      <origin
        xyz="-0.0237454614720194 0.00393636292072587 -0.00149999999999997"
        rpy="0 0 0" />
      <mass
        value="0.00146871763406109" />
      <inertia
        ixx="4.03152207786004E-08"
        ixy="1.04465154923335E-07"
        ixz="4.79764755280756E-23"
        iyy="4.31933892901021E-07"
        iyz="-1.32348898008484E-23"
        izz="4.7004603722853E-07" />
    </inertial>
    <visual>
      <origin
        xyz="0 0 0"
        rpy="0 0 0" />
      <geometry>
        <mesh
          filename="package://atomgrip1/meshes/Gripper5.2_link.STL" />
      </geometry>
      <material
        name="">
        <color
          rgba="0.647058823529412 0.619607843137255 0.588235294117647 1" />
      </material>
    </visual>
    <collision>
      <origin
        xyz="0 0 0"
        rpy="0 0 0" />
      <geometry>
        <mesh
          filename="package://atomgrip1/meshes/Gripper5.2_link.STL" />
      </geometry>
    </collision>
  </link>
  <joint
    name="Gripper5.2_joint"
    type="fixed">
    <origin
      xyz="-31 4 -3"
      rpy="3.14159265358979 0 -0.7" />
    <parent
      link="Gripper4.2_link" />
    <child
      link="Gripper5.2_link" />
    <axis
      xyz="0 0 1" />
  </joint>
  <link
    name="shoulder2elbow2.2_link">
    <inertial>
      <origin
        xyz="-0.038907 -0.01 0.097452"
        rpy="0 0 0" />
      <mass
        value="0.531909704004154" />
      <inertia
        ixx="6.10012709199159E-05"
        ixy="6.7762635780344E-21"
        ixz="9.3173624197973E-21"
        iyy="0.00115530662711474"
        iyz="-1.6940658945086E-21"
        izz="0.0011967441684999" />
    </inertial>
    <visual>
      <origin
        xyz="0 0 0"
        rpy="0 0 0" />
      <geometry>
        <mesh
          filename="package://atomgrip1/meshes/shoulder2elbow2.2_link.STL" />
      </geometry>
      <material
        name="">
        <color
          rgba="1 0.72156862745098 0.329411764705882 1" />
      </material>
    </visual>
    <collision>
      <origin
        xyz="0 0 0"
        rpy="0 0 0" />
      <geometry>
        <mesh
          filename="package://atomgrip1/meshes/shoulder2elbow2.2_link.STL" />
      </geometry>
    </collision>
  </link>
  <joint
    name="shoulder2elbow2.2_joint"
    type="revolute">
    <origin
      xyz="0 0 -91"
      rpy="0 -3.142 3.142" />
    <parent
      link="shoulder2elbow1_link" />
    <child
      link="shoulder2elbow2.2_link" />
    <axis
      xyz="0 0 -1" />
    <limit
      lower="-1.571"
      upper="1.571"
      effort="10"
      velocity="1" />
  </joint>
  <link
    name="elbow2twist2.2_link">
    <inertial>
      <origin
        xyz="0.0010394 0 0.0075"
        rpy="0 0 0" />
      <mass
        value="0.667644573828628" />
      <inertia
        ixx="7.77994390416781E-05"
        ixy="-4.40457132572236E-19"
        ixz="1.73641754187132E-20"
        iyy="0.00234823032643911"
        iyz="3.55753837846806E-20"
        izz="0.00240137155496887" />
    </inertial>
    <visual>
      <origin
        xyz="0 0 0"
        rpy="0 0 0" />
      <geometry>
        <mesh
          filename="package://atomgrip1/meshes/elbow2twist2.2_link.STL" />
      </geometry>
      <material
        name="">
        <color
          rgba="1 0.72156862745098 0.329411764705882 1" />
      </material>
    </visual>
    <collision>
      <origin
        xyz="0 0 0"
        rpy="0 0 0" />
      <geometry>
        <mesh
          filename="package://atomgrip1/meshes/elbow2twist2.2_link.STL" />
      </geometry>
    </collision>
  </link>
  <joint
    name="elbow2twist2.2_joint"
    type="revolute">
    <origin
      xyz="119 0 -15"
      rpy="3.14159265358979 0 3.142" />
    <parent
      link="shoulder2elbow2.2_link" />
    <child
      link="elbow2twist2.2_link" />
    <axis
      xyz="0 0 1" />
    <limit
      lower="0"
      upper="3.141"
      effort="10"
      velocity="1" />
  </joint>
</robot>